<?xml version="1.0"?>
<sdf version="1.9">
  <world name="teleop_course">
    <physics name="p" type="ignored"><max_step_size>0.004</max_step_size>
      <real_time_factor>1.0</real_time_factor></physics>
    <plugin filename="gz-sim-physics-system" name="gz::sim::systems::Physics"/>
    <plugin filename="gz-sim-user-commands-system"
            name="gz::sim::systems::UserCommands"/>
    <plugin filename="gz-sim-scene-broadcaster-system"
            name="gz::sim::systems::SceneBroadcaster"/>
    <light type="directional" name="sun"><cast_shadows>true</cast_shadows>
      <pose>0 0 10 0 0 0</pose><diffuse>0.9 0.85 0.8 1</diffuse>
      <direction>-0.4 0.2 -0.9</direction></light>
    <model name="ground"><static>true</static><link name="l">
      <collision name="c"><geometry><plane><normal>0 0 1</normal>
        <size>100 100</size></plane></geometry></collision>
      <visual name="v"><geometry><plane><normal>0 0 1</normal>
        <size>100 100</size></plane></geometry>
        <material><ambient>0.45 0.42 0.38 1</ambient>
        <diffuse>0.45 0.42 0.38 1</diffuse></material></visual></link></model>
    
    <model name="gate_0_0"><static>true</static>
      <pose>4.00 0.90 0.6 0 0 0</pose>
      <link name="l"><visual name="v"><geometry><cylinder>
        <radius>0.06</radius><length>1.2</length></cylinder></geometry>
        <material><ambient>0.85 0.45 0.18 1</ambient>
        <diffuse>0.85 0.45 0.18 1</diffuse></material></visual>
      <collision name="c"><geometry><cylinder><radius>0.06</radius>
        <length>1.2</length></cylinder></geometry></collision></link>
    </model>
    <model name="gate_0_1"><static>true</static>
      <pose>4.00 -0.90 0.6 0 0 0</pose>
      <link name="l"><visual name="v"><geometry><cylinder>
        <radius>0.06</radius><length>1.2</length></cylinder></geometry>
        <material><ambient>0.85 0.45 0.18 1</ambient>
        <diffuse>0.85 0.45 0.18 1</diffuse></material></visual>
      <collision name="c"><geometry><cylinder><radius>0.06</radius>
        <length>1.2</length></cylinder></geometry></collision></link>
    </model>
    <model name="gate_1_0"><static>true</static>
      <pose>8.00 3.40 0.6 0 0 0</pose>
      <link name="l"><visual name="v"><geometry><cylinder>
        <radius>0.06</radius><length>1.2</length></cylinder></geometry>
        <material><ambient>0.85 0.45 0.18 1</ambient>
        <diffuse>0.85 0.45 0.18 1</diffuse></material></visual>
      <collision name="c"><geometry><cylinder><radius>0.06</radius>
        <length>1.2</length></cylinder></geometry></collision></link>
    </model>
    <model name="gate_1_1"><static>true</static>
      <pose>8.00 1.60 0.6 0 0 0</pose>
      <link name="l"><visual name="v"><geometry><cylinder>
        <radius>0.06</radius><length>1.2</length></cylinder></geometry>
        <material><ambient>0.85 0.45 0.18 1</ambient>
        <diffuse>0.85 0.45 0.18 1</diffuse></material></visual>
      <collision name="c"><geometry><cylinder><radius>0.06</radius>
        <length>1.2</length></cylinder></geometry></collision></link>
    </model>
    <model name="gate_2_0"><static>true</static>
      <pose>12.00 -1.60 0.6 0 0 0</pose>
      <link name="l"><visual name="v"><geometry><cylinder>
        <radius>0.06</radius><length>1.2</length></cylinder></geometry>
        <material><ambient>0.85 0.45 0.18 1</ambient>
        <diffuse>0.85 0.45 0.18 1</diffuse></material></visual>
      <collision name="c"><geometry><cylinder><radius>0.06</radius>
        <length>1.2</length></cylinder></geometry></collision></link>
    </model>
    <model name="gate_2_1"><static>true</static>
      <pose>12.00 -3.40 0.6 0 0 0</pose>
      <link name="l"><visual name="v"><geometry><cylinder>
        <radius>0.06</radius><length>1.2</length></cylinder></geometry>
        <material><ambient>0.85 0.45 0.18 1</ambient>
        <diffuse>0.85 0.45 0.18 1</diffuse></material></visual>
      <collision name="c"><geometry><cylinder><radius>0.06</radius>
        <length>1.2</length></cylinder></geometry></collision></link>
    </model>
    <model name="gate_3_0"><static>true</static>
      <pose>16.00 3.40 0.6 0 0 0</pose>
      <link name="l"><visual name="v"><geometry><cylinder>
        <radius>0.06</radius><length>1.2</length></cylinder></geometry>
        <material><ambient>0.85 0.45 0.18 1</ambient>
        <diffuse>0.85 0.45 0.18 1</diffuse></material></visual>
      <collision name="c"><geometry><cylinder><radius>0.06</radius>
        <length>1.2</length></cylinder></geometry></collision></link>
    </model>
    <model name="gate_3_1"><static>true</static>
      <pose>16.00 1.60 0.6 0 0 0</pose>
      <link name="l"><visual name="v"><geometry><cylinder>
        <radius>0.06</radius><length>1.2</length></cylinder></geometry>
        <material><ambient>0.85 0.45 0.18 1</ambient>
        <diffuse>0.85 0.45 0.18 1</diffuse></material></visual>
      <collision name="c"><geometry><cylinder><radius>0.06</radius>
        <length>1.2</length></cylinder></geometry></collision></link>
    </model>
    <model name="gate_4_0"><static>true</static>
      <pose>20.00 -1.60 0.6 0 0 0</pose>
      <link name="l"><visual name="v"><geometry><cylinder>
        <radius>0.06</radius><length>1.2</length></cylinder></geometry>
        <material><ambient>0.85 0.45 0.18 1</ambient>
        <diffuse>0.85 0.45 0.18 1</diffuse></material></visual>
      <collision name="c"><geometry><cylinder><radius>0.06</radius>
        <length>1.2</length></cylinder></geometry></collision></link>
    </model>
    <model name="gate_4_1"><static>true</static>
      <pose>20.00 -3.40 0.6 0 0 0</pose>
      <link name="l"><visual name="v"><geometry><cylinder>
        <radius>0.06</radius><length>1.2</length></cylinder></geometry>
        <material><ambient>0.85 0.45 0.18 1</ambient>
        <diffuse>0.85 0.45 0.18 1</diffuse></material></visual>
      <collision name="c"><geometry><cylinder><radius>0.06</radius>
        <length>1.2</length></cylinder></geometry></collision></link>
    </model>
    <model name="gate_5_0"><static>true</static>
      <pose>24.00 0.90 0.6 0 0 0</pose>
      <link name="l"><visual name="v"><geometry><cylinder>
        <radius>0.06</radius><length>1.2</length></cylinder></geometry>
        <material><ambient>0.85 0.45 0.18 1</ambient>
        <diffuse>0.85 0.45 0.18 1</diffuse></material></visual>
      <collision name="c"><geometry><cylinder><radius>0.06</radius>
        <length>1.2</length></cylinder></geometry></collision></link>
    </model>
    <model name="gate_5_1"><static>true</static>
      <pose>24.00 -0.90 0.6 0 0 0</pose>
      <link name="l"><visual name="v"><geometry><cylinder>
        <radius>0.06</radius><length>1.2</length></cylinder></geometry>
        <material><ambient>0.85 0.45 0.18 1</ambient>
        <diffuse>0.85 0.45 0.18 1</diffuse></material></visual>
      <collision name="c"><geometry><cylinder><radius>0.06</radius>
        <length>1.2</length></cylinder></geometry></collision></link>
    </model>
    <model name="gate_6_0"><static>true</static>
      <pose>28.00 0.90 0.6 0 0 0</pose>
      <link name="l"><visual name="v"><geometry><cylinder>
        <radius>0.06</radius><length>1.2</length></cylinder></geometry>
        <material><ambient>0.85 0.45 0.18 1</ambient>
        <diffuse>0.85 0.45 0.18 1</diffuse></material></visual>
      <collision name="c"><geometry><cylinder><radius>0.06</radius>
        <length>1.2</length></cylinder></geometry></collision></link>
    </model>
    <model name="gate_6_1"><static>true</static>
      <pose>28.00 -0.90 0.6 0 0 0</pose>
      <link name="l"><visual name="v"><geometry><cylinder>
        <radius>0.06</radius><length>1.2</length></cylinder></geometry>
        <material><ambient>0.85 0.45 0.18 1</ambient>
        <diffuse>0.85 0.45 0.18 1</diffuse></material></visual>
      <collision name="c"><geometry><cylinder><radius>0.06</radius>
        <length>1.2</length></cylinder></geometry></collision></link>
    </model>
    <model name="rover">
      <pose>0 0 0.0 0 0 0</pose>
      <link name="chassis"><pose>0 0 0.18 0 0 0</pose>
        <inertial><mass>4.0</mass><inertia><ixx>0.05</ixx><iyy>0.09</iyy>
          <izz>0.12</izz><ixy>0</ixy><ixz>0</ixz><iyz>0</iyz></inertia></inertial>
        <visual name="v"><geometry><box><size>0.5 0.35 0.16</size></box>
          </geometry><material><ambient>0.18 0.45 0.8 1</ambient>
          <diffuse>0.18 0.45 0.8 1</diffuse></material></visual>
        <collision name="c"><geometry><box><size>0.5 0.35 0.16</size></box>
          </geometry></collision></link>
      
      <link name="left_wheel"><pose>0 0.21 0.12 -1.5708 0 0</pose>
        <inertial><mass>0.6</mass><inertia><ixx>0.002</ixx><iyy>0.002</iyy>
          <izz>0.004</izz><ixy>0</ixy><ixz>0</ixz><iyz>0</iyz></inertia></inertial>
        <visual name="v"><geometry><cylinder><radius>0.12</radius>
          <length>0.05</length></cylinder></geometry>
          <material><ambient>0.1 0.1 0.1 1</ambient></material></visual>
        <collision name="c"><geometry><cylinder><radius>0.12</radius>
          <length>0.05</length></cylinder></geometry>
          <surface><friction><ode><mu>1.1</mu><mu2>1.1</mu2></ode>
          </friction></surface></collision></link>
      <joint name="left_wheel_joint" type="revolute">
        <parent>chassis</parent><child>left_wheel</child>
        <axis><xyz>0 0 1</xyz></axis></joint>
      
      <link name="right_wheel"><pose>0 -0.21 0.12 -1.5708 0 0</pose>
        <inertial><mass>0.6</mass><inertia><ixx>0.002</ixx><iyy>0.002</iyy>
          <izz>0.004</izz><ixy>0</ixy><ixz>0</ixz><iyz>0</iyz></inertia></inertial>
        <visual name="v"><geometry><cylinder><radius>0.12</radius>
          <length>0.05</length></cylinder></geometry>
          <material><ambient>0.1 0.1 0.1 1</ambient></material></visual>
        <collision name="c"><geometry><cylinder><radius>0.12</radius>
          <length>0.05</length></cylinder></geometry>
          <surface><friction><ode><mu>1.1</mu><mu2>1.1</mu2></ode>
          </friction></surface></collision></link>
      <joint name="right_wheel_joint" type="revolute">
        <parent>chassis</parent><child>right_wheel</child>
        <axis><xyz>0 0 1</xyz></axis></joint>
      <link name="caster"><pose>0.2 0 0.05 0 0 0</pose>
        <inertial><mass>0.2</mass><inertia><ixx>0.0004</ixx><iyy>0.0004</iyy>
          <izz>0.0004</izz><ixy>0</ixy><ixz>0</ixz><iyz>0</iyz></inertia></inertial>
        <visual name="v"><geometry><sphere><radius>0.05</radius></sphere>
          </geometry></visual>
        <collision name="c"><geometry><sphere><radius>0.05</radius></sphere>
          </geometry><surface><friction><ode><mu>0.0</mu><mu2>0.0</mu2>
          </ode></friction></surface></collision></link>
      <joint name="caster_joint" type="ball">
        <parent>chassis</parent><child>caster</child></joint>
      <plugin filename="gz-sim-diff-drive-system"
              name="gz::sim::systems::DiffDrive">
        <left_joint>left_wheel_joint</left_joint>
        <right_joint>right_wheel_joint</right_joint>
        <wheel_separation>0.42</wheel_separation>
        <wheel_radius>0.12</wheel_radius>
        <odom_publish_frequency>30</odom_publish_frequency>
        <topic>/model/rover/cmd_vel</topic>
        <odom_topic>/model/rover/odometry</odom_topic>
      </plugin>
    </model>
  </world>
</sdf>
